Workbook
Name LIST_DATA_BARANG: #REF!
Name LIST_DATA_PELANGGAN: #REF!
Name LIST_KODE_DATABARANG: #REF!
Name LIST_NAMA_PELANGGAN: #REF!

Sheet 1. Purchase Order
A1: PT TEKNO BERSAMA | G1: PURCHASE ORDER
A4: Jl. Jenderal Sudirman No. 45, Jakarta Pusat, 10220
A5: Telp: (021) 777-8889 | Email: | G5: NO. PO | H5: PO/TB/08/2026/045
A6: purchasing@teknobersama.com | G6: TANGGAL | H6: =NOW() -> 46261.886
A7: NPWP: 01.234.567.8-091.000
A9: INFORMASI VENDOR | F9: KIRIM KE (SHIPPING)
A11: =_xlfn.XLOOKUP($H$5,Tabel_Vendor[Nomor PO],Tabel_Vendor[Perusahaan Vendor]," - ") -> PT. BeSmart Indonesia Gemilang | F11: Gudang PT. Tekno Bersama Jatiuwung
A12: =_xlfn.XLOOKUP($H$5,Tabel_Vendor[Nomor PO],Tabel_Vendor[Alamat Vendor]," - ") -> Jl. Merdeka Indonesia, Kota Tangerang | F12: =_xlfn.XLOOKUP(F11,Tabel_Shipping[Perusahaan Shipping],Tabel_Shipping[Alamat Shipping]," - ") -> Kawasan Industri Pulo Pasar Jati, Jatiuwung
F14: UP | H14: =_xlfn.XLOOKUP(F11,Tabel_Shipping[Perusahaan Shipping],Tabel_Shipping[UP Shipping]," - ") -> Rizky Faisal Rafi
A15: UP | B15: =_xlfn.XLOOKUP($H$5,Tabel_Vendor[Nomor PO],Tabel_Vendor[UP Vendor]," - ") -> Gibran Raka | F15: Telp | H15: =_xlfn.XLOOKUP(F11,Tabel_Shipping[Perusahaan Shipping],Tabel_Shipping[Telp Shipping]," - ") -> 0895-1XXX-6XXX
A16: Telp | B16: =_xlfn.XLOOKUP($H$5,Tabel_Vendor[Nomor PO],Tabel_Vendor[Telp]," - ") -> 0812-XXXX-XXXX | F16: Tgl. Diharapkan | H16: =_xlfn.XLOOKUP($H$5,Tabel_Vendor[Nomor PO],Tabel_Vendor[Tanggal Diaharapkan]," - ") -> 46264
A18: NO. | B18: KODE | C18: DESKRIPSI BARANG | F18: QTY | G18: HARGA | I18: TOTAL
A19: 1 | B19: A01 | C19: =_xlfn.XLOOKUP(B19,'Master Data'!$B$3:$B$12,'Master Data'!$C$3:$C$12," ",0) -> Mouse Gaming | F19: 30 | G19: =_xlfn.XLOOKUP(B19,'Master Data'!$B$3:$B$12,'Master Data'!$D$3:$D$12," ",0) -> 40000 | I19: =IFERROR(G19 * F19," ") -> 1200000
A20: 2 | B20: A02 | C20: =_xlfn.XLOOKUP(B20,'Master Data'!$B$3:$B$12,'Master Data'!$C$3:$C$12," ",0) -> Keyboard | F20: 12 | G20: =_xlfn.XLOOKUP(B20,'Master Data'!$B$3:$B$12,'Master Data'!$D$3:$D$12," ",0) -> 60000 | I20: =IFERROR(G20 * F20," ") -> 720000
A21: 3 | B21: A03 | C21: =_xlfn.XLOOKUP(B21,'Master Data'!$B$3:$B$12,'Master Data'!$C$3:$C$12," ",0) -> Harddisk Eksternal 512GB | F21: 13 | G21: =_xlfn.XLOOKUP(B21,'Master Data'!$B$3:$B$12,'Master Data'!$D$3:$D$12," ",0) -> 2000000 | I21: =IFERROR(G21 * F21," ") -> 26000000
A22: 4 | B22: A04 | C22: =_xlfn.XLOOKUP(B22,'Master Data'!$B$3:$B$12,'Master Data'!$C$3:$C$12," ",0) -> Monitor LED | F22: 10 | G22: =_xlfn.XLOOKUP(B22,'Master Data'!$B$3:$B$12,'Master Data'!$D$3:$D$12," ",0) -> 2000000 | I22: =IFERROR(G22 * F22," ") -> 20000000
A23: 5 | B23: A06 | C23: =_xlfn.XLOOKUP(B23,'Master Data'!$B$3:$B$12,'Master Data'!$C$3:$C$12," ",0) -> Kursi Gaming | F23: 6 | G23: =_xlfn.XLOOKUP(B23,'Master Data'!$B$3:$B$12,'Master Data'!$D$3:$D$12," ",0) -> 1500000 | I23: =IFERROR(G23 * F23," ") -> 9000000
A24: 6 | B24: A07 | C24: =_xlfn.XLOOKUP(B24,'Master Data'!$B$3:$B$12,'Master Data'!$C$3:$C$12," ",0) -> Headset Gaming | F24: 9 | G24: =_xlfn.XLOOKUP(B24,'Master Data'!$B$3:$B$12,'Master Data'!$D$3:$D$12," ",0) -> 40000 | I24: =IFERROR(G24 * F24," ") -> 360000
A25: 7 | B25: A10 | C25: =_xlfn.XLOOKUP(B25,'Master Data'!$B$3:$B$12,'Master Data'!$C$3:$C$12," ",0) -> Speaker Super Bass | F25: 12 | G25: =_xlfn.XLOOKUP(B25,'Master Data'!$B$3:$B$12,'Master Data'!$D$3:$D$12," ",0) -> 180000 | I25: =IFERROR(G25 * F25," ") -> 2160000
A26: 8 | B26: A09 | C26: =_xlfn.XLOOKUP(B26,'Master Data'!$B$3:$B$12,'Master Data'!$C$3:$C$12," ",0) -> Meja PC Gaming | F26: 5 | G26: =_xlfn.XLOOKUP(B26,'Master Data'!$B$3:$B$12,'Master Data'!$D$3:$D$12," ",0) -> 1200000 | I26: =IFERROR(G26 * F26," ") -> 6000000
G27: SUB TOTAL | I27: =SUM(I19:I26) -> 65440000
A28: Syarat & Ketentuan:
A29: 1. Termin Pembayaran: Net 30 Days setelah invoice diterima. | G29: PPN (11%) | I29: =I27 * MID(G29,6,3) -> 7198400
A30: 2. Nomor PO wajib dicantumkan pada Surat Jalan dan Invoice / Faktur.
A31: 3. Barang harus dikirim dalam kondisi baru, original, dan dipacking aman. | G31: TOTAL | I31: =SUM(I27:I30) -> 72638400
A32: 4. Keterlambatan pengiriman dapat mengakibatkan pembatalan PO.
A38: Dibuat Oleh, | D38: Disetujui Oleh, | H38: Konfirrmasi & CAP,
A44: Staff Purchasing | D44: Manajer Keuangan | H44: Pihak Vendor

Sheet 2. Surat Jalan
B2: PT. BeSmart Indonesia Gemilang
B3: Jl. Merdeka Indonesia, Kota Tangerang
B4: Telp: (021) 555-1234 | Email: info@besmartindogem.com
B6: Surat Jalan
C8: No. Surat Jalan | D8: SJ/08/2026/001 | F8: Kepada Yth, | G8: =_xlfn.XLOOKUP($D$8,Data_Tujuan[No Surat Jalan],Data_Tujuan[Nama Perusahaan]," ") -> PT. Tekno Bersama
C9: Tanggal | D9: =_xlfn.XLOOKUP($D$8, Data_Tujuan[No Surat Jalan],Data_Tujuan[Tanggal]," ") -> 46261 | G9: {=_xlfn.XLOOKUP($D$8,Data_Tujuan[No Surat Jalan],_xlfn.TEXTBEFORE(Data_Tujuan[Alamat Perusahaan], ",")," ")} -> Kawasan Industri Pulo Pasar Jati
D10: =_xlfn.XLOOKUP($D$8, Data_Tujuan[No Surat Jalan],Data_Tujuan[No. PO/Ref]," ") -> PO/TB/08/2026/045 | G10: {=_xlfn.XLOOKUP($D$8,Data_Tujuan[No Surat Jalan],_xlfn.TEXTAFTER(Data_Tujuan[Alamat Perusahaan], ", "), " ")} -> Jatiuwung
C11: Nama Supir | D11: =_xlfn.XLOOKUP($D$8, Data_Tujuan[No Surat Jalan],Data_Tujuan[Nama Supir]," ") -> Jaka Sembung
C12: No. Polisi | D12: =_xlfn.XLOOKUP($D$8, Data_Tujuan[No Surat Jalan],Data_Tujuan[No. Polisi]," ") -> B 7979 AB | F12: UP | G12: =_xlfn.XLOOKUP($D$8,Data_Tujuan[No Surat Jalan],Data_Tujuan[Untuk Perhatian], " ") -> Rizky Faisal Rafi
B14: Harap diterima dengan baik barang-barang di bawah ini:
B16: No. | C16: Kode Barang | D16: NAMA / DESKRIPSI BARANG | E16: QTY | F16: Satuan | G16: Keterangan
B17: 1 | C17: ='1. Purchase Order'!B19 -> A01 | D17: =VLOOKUP(C17,'1. Purchase Order'!$B$19:$I$26,2,FALSE) -> Mouse Gaming | E17: =_xlfn.XLOOKUP(C17,'1. Purchase Order'!$B$19:$B$26,'1. Purchase Order'!$F$19:$F$26, " ",) -> 30 | F17: Piece | G17: Packing Kayu
B18: 2 | C18: ='1. Purchase Order'!B20 -> A02 | D18: =VLOOKUP(C18,'1. Purchase Order'!$B$19:$I$26,2) -> Keyboard | E18: =_xlfn.XLOOKUP(C18,'1. Purchase Order'!$B$19:$B$26,'1. Purchase Order'!$F$19:$F$26, " ",) -> 12 | F18: Piece | G18: Packing Kayu
B19: 3 | C19: ='1. Purchase Order'!B21 -> A03 | D19: =VLOOKUP(C19,'1. Purchase Order'!$B$19:$I$26,2) -> Harddisk Eksternal 512GB | E19: =_xlfn.XLOOKUP(C19,'1. Purchase Order'!$B$19:$B$26,'1. Purchase Order'!$F$19:$F$26, " ",) -> 13 | F19: Piece | G19: Packing Kayu
B20: 4 | C20: ='1. Purchase Order'!B22 -> A04 | D20: =VLOOKUP(C20,'1. Purchase Order'!$B$19:$I$26,2) -> Monitor LED | E20: =_xlfn.XLOOKUP(C20,'1. Purchase Order'!$B$19:$B$26,'1. Purchase Order'!$F$19:$F$26, " ",) -> 10 | F20: Piece | G20: Packing Kayu
B21: 5 | C21: ='1. Purchase Order'!B23 -> A06 | D21: =VLOOKUP(C21,'1. Purchase Order'!$B$19:$I$26,2) -> Kursi Gaming | E21: =_xlfn.XLOOKUP(C21,'1. Purchase Order'!$B$19:$B$26,'1. Purchase Order'!$F$19:$F$26, " ",) -> 6 | F21: Piece | G21: Packing Kayu
B22: 6 | C22: ='1. Purchase Order'!B24 -> A07 | D22: =VLOOKUP(C22,'1. Purchase Order'!$B$19:$I$26,2) -> Headset Gaming | E22: =_xlfn.XLOOKUP(C22,'1. Purchase Order'!$B$19:$B$26,'1. Purchase Order'!$F$19:$F$26, " ",) -> 9 | F22: Piece | G22: Packing Kayu
B23: 7 | C23: ='1. Purchase Order'!B25 -> A10 | D23: =VLOOKUP(C23,'1. Purchase Order'!$B$19:$I$26,2) -> Speaker Super Bass | E23: =_xlfn.XLOOKUP(C23,'1. Purchase Order'!$B$19:$B$26,'1. Purchase Order'!$F$19:$F$26, " ",) -> 12 | F23: Piece | G23: Packing Kayu
B26: Catatan:
B27: Barang yang sudah dibeli tidak dapat ditukar atau dikembalikan kecuali ada perjanjian sebelumnya.
B28: Surat jalan ini merupakan bukti serah terima barang yang sah.
C37: Diterima Oleh, | D37: Dibawa Oleh, | G37: Dibuat Oleh,
D46: ="( " & D11 & " )" -> ( Jaka Sembung ) | G46: ( Admin Gudang )
C47: Nama Penerima | D47: Supir / Kurir | G47: Pengirim

Sheet 3. BAST
A1: PT. BESMART INDONESIA GEMILANG
A2: Jl. Merdeka Indonesia, Kota Tangerang
A3: Telp: 0812-XXXX-XXXX | Email: info@besmartindo.com
A6: BERITA ACARA SERAH TERIMA BARANG
A7: Nomor: BAST/BG/08/2026/088
A9: Pada hari ini, Senin, tanggal Tiga Puluh Satu, bulan Agustus, tahun Dua Ribu Dua Puluh Enam (31-08-2026), bertempat di Gudang PT. Tekno Bersama (Kota Tangerang), kami yang bertanda tangan di bawah ini:
A11: 1. | B11: PIHAK PERTAMA (Yang Menyerahkan)
B12: Nama | E12: Gibran Raka
B13: Jabatan | E13: Sales Manajer
B14: Perusahaan | E14: PT. BESMART INDONESIA GEMILANG
B15: Alamat | E15: Jl. Merdeka Indonesia, Kota Tangerang
A17: 2. | B17: PIHAK KEDUA (Yang Menerima)
B18: Nama | E18: Rizky Faisal Rafi
B19: Jabatan | E19: Kepala Bagian Penerimaan
B20: Perusahaan | E20: PT. TEKNO BERSAMA
B21: Alamat | E21: Kawasan Industri Pulo Pasar Jati, Jatiuwung
A23: Kedua belah pihak dengan ini menerangkan dan menyatakan hal-hal sebagai berikut:
A25: 1. | B25: PIHAK PERTAMA telah menyerahkan barang kepada PIHAK KEDUA, dan PIHAK KEDUA
B26: telah menerima penyerahan barang dari PIHAK PERTAMA, berdasarkan dokumen
B27: pemesanan:
B28: A. Nomor Purchase Order (PO): PO/TB/08/2026/045
B29: B. Nomor Surat Jalan: SJ/BG/08/2026/102
A31: 2. | B31: Adapun rincian barang yang diserahterimakan adalah sebagai berikut:
B33: NO. | C33: KODE | D33: DESKRIPSI BARANG | H33: QTY
B34: 1 | C34: A01 | D34: =_xlfn.XLOOKUP(C34,'Master Data'!$B$3:$B$12,'Master Data'!$C$3:$C$12," ",0) -> Mouse Gaming | H34: 30 Unit
B35: 2 | C35: A02 | D35: =_xlfn.XLOOKUP(C35,'Master Data'!$B$3:$B$12,'Master Data'!$C$3:$C$12," ",0) -> Keyboard | H35: 12 Unit
B36: 3 | C36: A03 | D36: =_xlfn.XLOOKUP(C36,'Master Data'!$B$3:$B$12,'Master Data'!$C$3:$C$12," ",0) -> Harddisk Eksternal 512GB | H36: 13 Unit
B37: 4 | C37: A04 | D37: =_xlfn.XLOOKUP(C37,'Master Data'!$B$3:$B$12,'Master Data'!$C$3:$C$12," ",0) -> Monitor LED | H37: 5 Unit
B38: 5 | C38: A06 | D38: =_xlfn.XLOOKUP(C38,'Master Data'!$B$3:$B$12,'Master Data'!$C$3:$C$12," ",0) -> Kursi Gaming | H38: 6 Unit
B39: 6 | C39: A07 | D39: =_xlfn.XLOOKUP(C39,'Master Data'!$B$3:$B$12,'Master Data'!$C$3:$C$12," ",0) -> Headset Gaming | H39: 9 Unit
B40: 7 | C40: A10 | D40: =_xlfn.XLOOKUP(C40,'Master Data'!$B$3:$B$12,'Master Data'!$C$3:$C$12," ",0) -> Speaker Super Bass | H40: 12 Unit
B41: 8 | C41: A09 | D41: =_xlfn.XLOOKUP(C41,'Master Data'!$B$3:$B$12,'Master Data'!$C$3:$C$12," ",0) -> Meja PC Gaming | H41: 5 Unit
A43: 3. | B43: PIHAK KEDUA menyatakan bahwa seluruh barang yang diserahkan oleh PIHAK PERTAMA
B44: telah diperiksa dan diterima dalam keadaan lengkap, baru, dapat berfungsi dengan baik,
B45: serta sesuai dengan spesifikasi yang disepakati pada Purchase Order.
A47: 4. | B47: Dengan ditandatanganinya Berita Acara Serah Terima Barang ini, maka tanggung jawab atas
B48: keamanan dan pemeliharaan barang berpindah dari PIHAK PERTAMA kepada PIHAK KEDUA,
B49: dan PIHAK PERTAMA berhak untuk memproses penagihan (Invoice).
A51: Demikian Berita Acara Serah Terima Barang ini dibuat dalam rangkap 2 (dua) yang memiliki
A52: kekuatan hukum yang sama, untuk dapat dipergunakan sebagaimana mestinya.
...

Sheet 4. Surat Retur
B2: PT. TEKNO BERSAMA | G2: RETURN NOTE
B4: Kawasan Industri Pulo Pasar Jati, Jatiuwung | G4: NO. RETURN | I4: RET/TB/08/2026/001
B5: Telp: (021) 777-8889 | Email: warehouse@teknobersama.com | G5: TANGGAL | I5: 46265
B8: DIKEMBALIKAN KEPADA (VENDOR) | G8: REFERENSI DOKUMEN
B11: PT. BESMART INDONESIA GEMILANG | G11: No. Surat Jalan Asli | I11: SJ/BG/08/2026/102
B12: =_xlfn.XLOOKUP(B11,Tabel_Vendor[Perusahaan Vendor],Tabel_Vendor[Alamat Vendor]," ") -> Jl. Merdeka Indonesia, Kota Tangerang
G13: Tanggal Pengiriman | I13: 46265
B15: UP | C15: Bagian Retur / Gudang Penerimaan | G15: No. PO Referensi | I15: PO/TB/08/2026/045
B19: Barang - barang berikut dikembalikan karena tidak memenuhi standar kualitas / mengalami kerusakan:
B21: NO. | C21: KODE | D21: DESKRIPSI BARANG | G21: QTY | H21: SATUAN | I21: ALASAN RETUR
B22: 1 | C22: A04 | D22: =_xlfn.XLOOKUP(C22,'Master Data'!B3:B12,'Master Data'!C3:C12," ") -> Monitor LED | G22: 5 | H22: Piece | I22: Layar pecah saat dibongkar
B26: TINDAK LANJUT YANG DIHARAPKAN:
B28: Mohon segera diproses untuk Penggantian Barang Baru (Replacement) dan dikirimkan kembali ke
B29: gudang kami selambat-lambatnya tanggal 3 September 2026
B46: Diserahkan Oleh, | E46: Dibawa Oleh, | H46: Diterima Oleh,
B55: (...................................................) | E55: (...................................................) | H55: (...................................................)
B56: Diserahkan (Kepala Gudang) | E56: Supir / Kurir | H56: Diterima (Gudang Vendor)

Sheet 5. Faktur Invoice
C3: FAKTUR INVOICE
H5: Kota Tangerang, 30 Agustus 2026
C6: PT. BeSmart Indonesia Gemilang | H6: Kepada Yth.
C7: =_xlfn.TEXTBEFORE(_xlfn.XLOOKUP(C6,'Master Data'!H3:H8,'Master Data'!I3:I8," "),",") -> Jl. Merdeka Indonesia | H7: Gudang PT. Tekno Bersama Cikupa
C8: =UPPER(_xlfn.TEXTAFTER(_xlfn.XLOOKUP(C6,'Master Data'!H3:H8,'Master Data'!I3:I8," "),", ")) -> KOTA TANGERANG | H8: =VLOOKUP(H7,'Master Data'!G17:J18,2,FALSE) -> Kawasan Industri Pulo Gadung Blok A1, Cikupa
C9: =(_xlfn.XLOOKUP(C6,'Master Data'!H3:H8,'Master Data'!K3:K8," ")) -> 0812-XXXX-XXXX | H9: =VLOOKUP(H7,'Master Data'!G17:J18,4,FALSE) -> 0812-XXXX-6XXX
C11: Nomor Faktur : | E11: 001/08/2026
C13: No. | D13: Kode | E13: Nama Barang | F13: Jumlah | G13: Harga Satuan | H13: Diskon | I13: Total
C14: 1 | D14: ='1. Purchase Order'!B19 -> A01 | E14: =IFERROR(VLOOKUP(D14,Tabel_Barang[[Kode]:[Harga]],2,FALSE),"Terjadi Kesalahan") -> Mouse Gaming | F14: =_xlfn.XLOOKUP(Table5[[#This Row],[Kode]],'1. Purchase Order'!$B$19:$B$26,'1. Purchase Order'!$F$19:$F$26, " ",) -> 30 | G14: =_xlfn.XLOOKUP(Table5[[#This Row],[Kode]],'Master Data'!$B$3:$B$12,'Master Data'!$D$3:$D$12," ",0) -> 40000 | H14: =IFERROR(IF(F14>=12, Table5[[#This Row],[Harga Satuan]] * Table5[[#This Row],[Jumlah]] * 10%, 0),"Terjadi Kesalahan") -> 120000 | I14: =IFERROR(Table5[[#This Row],[Jumlah]]*Table5[[#This Row],[Harga Satuan]]-Table5[[#This Row],[Diskon]],"Terjadi Kesalahan") -> 1080000
C15: 2 | D15: ='1. Purchase Order'!B20 -> A02 | E15: =IFERROR(VLOOKUP(D15,Tabel_Barang[[Kode]:[Harga]],2,FALSE),"Terjadi Kesalahan") -> Keyboard | F15: =_xlfn.XLOOKUP(Table5[[#This Row],[Kode]],'1. Purchase Order'!$B$19:$B$26,'1. Purchase Order'!$F$19:$F$26, " ",) -> 12 | G15: =_xlfn.XLOOKUP(Table5[[#This Row],[Kode]],'Master Data'!$B$3:$B$12,'Master Data'!$D$3:$D$12," ",0) -> 60000 | H15: =IFERROR(IF(F15>=12, Table5[[#This Row],[Harga Satuan]] * Table5[[#This Row],[Jumlah]] * 10%, 0),"Terjadi Kesalahan") -> 72000 | I15: =IFERROR(Table5[[#This Row],[Jumlah]]*Table5[[#This Row],[Harga Satuan]]-Table5[[#This Row],[Diskon]],"Terjadi Kesalahan") -> 648000
C16: 3 | D16: ='1. Purchase Order'!B21 -> A03 | E16: =IFERROR(VLOOKUP(D16,Tabel_Barang[[Kode]:[Harga]],2,FALSE),"Terjadi Kesalahan") -> Harddisk Eksternal 512GB | F16: =_xlfn.XLOOKUP(Table5[[#This Row],[Kode]],'1. Purchase Order'!$B$19:$B$26,'1. Purchase Order'!$F$19:$F$26, " ",) -> 13 | G16: =_xlfn.XLOOKUP(Table5[[#This Row],[Kode]],'Master Data'!$B$3:$B$12,'Master Data'!$D$3:$D$12," ",0) -> 2000000 | H16: =IFERROR(IF(F16>=12, Table5[[#This Row],[Harga Satuan]] * Table5[[#This Row],[Jumlah]] * 10%, 0),"Terjadi Kesalahan") -> 2600000 | I16: =IFERROR(Table5[[#This Row],[Jumlah]]*Table5[[#This Row],[Harga Satuan]]-Table5[[#This Row],[Diskon]],"Terjadi Kesalahan") -> 23400000
C17: 4 | D17: ='1. Purchase Order'!B22 -> A04 | E17: =IFERROR(VLOOKUP(D17,Tabel_Barang[[Kode]:[Harga]],2,FALSE),"Terjadi Kesalahan") -> Monitor LED | F17: =_xlfn.XLOOKUP(Table5[[#This Row],[Kode]],'1. Purchase Order'!$B$19:$B$26,'1. Purchase Order'!$F$19:$F$26, " ",) - 5 -> 5 | G17: =_xlfn.XLOOKUP(Table5[[#This Row],[Kode]],'Master Data'!$B$3:$B$12,'Master Data'!$D$3:$D$12," ",0) -> 2000000 | H17: =IFERROR(IF(F17>=12, Table5[[#This Row],[Harga Satuan]] * Table5[[#This Row],[Jumlah]] * 10%, 0),"Terjadi Kesalahan") -> 0 | I17: =IFERROR(Table5[[#This Row],[Jumlah]]*Table5[[#This Row],[Harga Satuan]]-Table5[[#This Row],[Diskon]],"Terjadi Kesalahan") -> 10000000
C18: 5 | D18: ='1. Purchase Order'!B23 -> A06 | E18: =IFERROR(VLOOKUP(D18,Tabel_Barang[[Kode]:[Harga]],2,FALSE),"Terjadi Kesalahan") -> Kursi Gaming | F18: =_xlfn.XLOOKUP(Table5[[#This Row],[Kode]],'1. Purchase Order'!$B$19:$B$26,'1. Purchase Order'!$F$19:$F$26, " ",) -> 6 | G18: =_xlfn.XLOOKUP(Table5[[#This Row],[Kode]],'Master Data'!$B$3:$B$12,'Master Data'!$D$3:$D$12," ",0) -> 1500000 | H18: =IFERROR(IF(F18>=12, Table5[[#This Row],[Harga Satuan]] * Table5[[#This Row],[Jumlah]] * 10%, 0),"Terjadi Kesalahan") -> 0 | I18: =IFERROR(Table5[[#This Row],[Jumlah]]*Table5[[#This Row],[Harga Satuan]]-Table5[[#This Row],[Diskon]],"Terjadi Kesalahan") -> 9000000
C19: 6 | D19: ='1. Purchase Order'!B24 -> A07 | E19: =IFERROR(VLOOKUP(D19,Tabel_Barang[[Kode]:[Harga]],2,FALSE),"Terjadi Kesalahan") -> Headset Gaming | F19: =_xlfn.XLOOKUP(Table5[[#This Row],[Kode]],'1. Purchase Order'!$B$19:$B$26,'1. Purchase Order'!$F$19:$F$26, " ",) -> 9 | G19: =_xlfn.XLOOKUP(Table5[[#This Row],[Kode]],'Master Data'!$B$3:$B$12,'Master Data'!$D$3:$D$12," ",0) -> 40000 | H19: =IFERROR(IF(F19>=12, Table5[[#This Row],[Harga Satuan]] * Table5[[#This Row],[Jumlah]] * 10%, 0),"Terjadi Kesalahan") -> 0 | I19: =IFERROR(Table5[[#This Row],[Jumlah]]*Table5[[#This Row],[Harga Satuan]]-Table5[[#This Row],[Diskon]],"Terjadi Kesalahan") -> 360000
C20: 7 | D20: ='1. Purchase Order'!B25 -> A10 | E20: =IFERROR(VLOOKUP(D20,Tabel_Barang[[Kode]:[Harga]],2,FALSE),"Terjadi Kesalahan") -> Speaker Super Bass | F20: =_xlfn.XLOOKUP(Table5[[#This Row],[Kode]],'1. Purchase Order'!$B$19:$B$26,'1. Purchase Order'!$F$19:$F$26, " ",) -> 12 | G20: =_xlfn.XLOOKUP(Table5[[#This Row],[Kode]],'Master Data'!$B$3:$B$12,'Master Data'!$D$3:$D$12," ",0) -> 180000 | H20: =IFERROR(IF(F20>=12, Table5[[#This Row],[Harga Satuan]] * Table5[[#This Row],[Jumlah]] * 10%, 0),"Terjadi Kesalahan") -> 216000 | I20: =IFERROR(Table5[[#This Row],[Jumlah]]*Table5[[#This Row],[Harga Satuan]]-Table5[[#This Row],[Diskon]],"Terjadi Kesalahan") -> 1944000
C21: 8 | D21: ='1. Purchase Order'!B26 -> A09 | E21: =IFERROR(VLOOKUP(D21,Tabel_Barang[[Kode]:[Harga]],2,FALSE),"Terjadi Kesalahan") -> Meja PC Gaming | F21: =_xlfn.XLOOKUP(Table5[[#This Row],[Kode]],'1. Purchase Order'!$B$19:$B$26,'1. Purchase Order'!$F$19:$F$26, " ",) -> 5 | G21: =_xlfn.XLOOKUP(Table5[[#This Row],[Kode]],'Master Data'!$B$3:$B$12,'Master Data'!$D$3:$D$12," ",0) -> 1200000 | H21: =IFERROR(IF(F21>=12, Table5[[#This Row],[Harga Satuan]] * Table5[[#This Row],[Jumlah]] * 10%, 0),"Terjadi Kesalahan") -> 0 | I21: =IFERROR(Table5[[#This Row],[Jumlah]]*Table5[[#This Row],[Harga Satuan]]-Table5[[#This Row],[Diskon]],"Terjadi Kesalahan") -> 6000000
G22: Sub Total | I22: =IFERROR(SUM(I14:I21),"Terjadi Kesalahan") -> 52432000
G23: Total Diskon | I23: =IFERROR(SUM(H14:H21),"Terjadi Kesalahan") -> 3008000
G24: Pajak 11% | I24: =IFERROR((I22-I23)*11%,"Terjadi Kesalahan") -> 5436640
G25: Yang Dibayar | I25: =IFERROR(I22-I23+I24,"Terjadi Kesalahan") -> 54860640

Sheet 6. Kwitansi
B6: TELAH TERIMA DARI | C6: PT. TEKNO BERSAMA
B8: Rp. | C8: ='5. Faktur Invoice'!I25 -> 54860640
B10: UANG SEJUMLAH | C10: # LIMA PULUH EMPAT JUTA DELAPAN RATUS ENAM PULUH ENAM RATUS EMPAT PULUH RIBU RUPIAH #
B12: UNTUK PEMBAYARAN | C12: Pelunasan Tagihan Invoice No. 001/08/2026 atas pengadaan perangkat IT (berdasarkan PO/TB/08/2026/045).
H17: Kota Tangerang, 10 September 2026
H25: Rizky Faisal Rafi
H26: Finance / Penerima

Sheet Master Data
N1: Data Surat Jalan
A2: No. | B2: Kode | C2: Deskripsi Barang | D2: Harga | F2: No. | G2: Nomor PO | H2: Perusahaan Vendor | I2: Alamat Vendor | J2: UP Vendor | K2: Telp | L2: Tanggal Diaharapkan | N2: No. | O2: No Surat Jalan | P2: Tanggal | Q2: No. PO/Ref | R2: Nama Supir | S2: No. Polisi | T2: Nama Perusahaan | U2: Untuk Perhatian | V2: Alamat Perusahaan
A3: 1 | B3: A01 | C3: Mouse Gaming | D3: 40000 | F3: 1 | G3: PO/TB/08/2026/045 | H3: PT. BeSmart Indonesia Gemilang | I3: Jl. Merdeka Indonesia, Kota Tangerang | J3: Gibran Raka | K3: 0812-XXXX-XXXX | L3: 46264 | N3: 1 | O3: SJ/08/2026/001 | P3: 46261 | Q3: PO/TB/08/2026/045 | R3: Jaka Sembung | S3: B 7979 AB | T3: PT. Tekno Bersama | U3: Rizky Faisal Rafi | V3: Kawasan Industri Pulo Pasar Jati, Jatiuwung
A4: 2 | B4: A02 | C4: Keyboard | D4: 60000 | F4: 2 | G4: PO/TB/08/2026/046 | H4: PT Shan Information | I4: Jl. Jend. Sudirman No. 52, Jakarta Selatan | J4: Jokowi | K4: 0813-XXXX-XXXX | L4: 46265 | N4: 2 | O4: SJ/08/2026/002 | P4: 46262 | Q4: PO/TB/08/2026/046 | R4: Dodi Mulyanto | S4: B 0678 AB | T4: PT Shan Information | U4: Fajar Andana | V4: Jl. Jend. Sudirman No. 45, Jakarta Barat
A5: 3 | B5: A03 | C5: Harddisk Eksternal 512GB | D5: 2000000 | F5: 3 | G5: PO/TB/08/2026/047 | H5: PT Anugrah Hadi Electric | I5: Jl. Jend. Sudirman No. 53, Jakarta Barat | J5: Prabowo | K5: 0814-XXXX-XXXX | L5: 46266
A6: 4 | B6: A04 | C6: Monitor LED | D6: 2000000 | F6: 4 | G6: PO/TB/08/2026/048 | H6: PT Janji Manis Sentosa | I6: Jl. Jend. Sudirman No. 54, Jakarta Selatan | J6: Anis | K6: 0815-XXXX-XXXX | L6: 46267
A7: 5 | B7: A05 | C7: CPU | D7: 5000000 | F7: 5 | G7: PO/TB/08/2026/049 | H7: PT Maju Jaya Bersama | I7: Jl. Jend. Sudirman No. 55, Jakarta Barat | J7: Ahok | K7: 0816-XXXX-XXXX | L7: 46268
A8: 6 | B8: A06 | C8: Kursi Gaming | D8: 1500000 | F8: 6 | G8: PO/TB/08/2026/050 | H8: PT Tokopaedi Indonesia | I8: Jl. Jend. Sudirman No. 56, Jakarta Selatan | J8: Ganjar | K8: 0817-XXXX-XXXX | L8: 46269
A9: 7 | B9: A07 | C9: Headset Gaming | D9: 40000
A10: 8 | B10: A08 | C10: Sarung Jempol Gaming | D10: 15000
A11: 9 | B11: A09 | C11: Meja PC Gaming | D11: 1200000
A12: 10 | B12: A10 | C12: Speaker Super Bass | D12: 180000
F16: No. | G16: Perusahaan Shipping | H16: Alamat Shipping | I16: UP Shipping | J16: Telp Shipping
F17: 1 | G17: Gudang PT. Tekno Bersama Cikupa | H17: Kawasan Industri Pulo Gadung Blok A1, Cikupa | I17: Herman Wia Jaya | J17: 0812-XXXX-6XXX
F18: 2 | G18: Gudang PT. Tekno Bersama Jatiuwung | H18: Kawasan Industri Pulo Pasar Jati, Jatiuwung | I18: Rizky Faisal Rafi | J18: 0895-1XXX-6XXX
